<?xml version="1.0" encoding="utf-8" ?>
<!-- This URDF was automatically created by SolidWorks to URDF Exporter! Originally created by Stephen Brawner (brawner@gmail.com) 
     Commit Version: 1.6.0-4-g7f85cfe  Build Version: 1.6.7995.38578
     For more information, please see http://wiki.ros.org/sw_urdf_exporter -->
<robot name="haiheng-URDF">
    <link name="BASE_S">
        <inertial>
            <origin xyz="-0.0350295277529371 0.00012890818545074 0.0289333464196604" rpy="0 0 0" />
            <mass value="0.622658635770986" />
            <inertia ixx="0.000821694226117557" ixy="-7.11084014488264E-08" ixz="0.000220776521565022" iyy="0.000989737080483807" iyz="2.90563863004685E-06" izz="0.00107502812957434" />
        </inertial>
        <visual>
            <origin xyz="0 0 0" rpy="0 0 0" />
            <geometry>
                <mesh filename="package://haiheng-URDF/meshes/BASE_S.STL" />
            </geometry>
            <material name="">
                <color rgba="0.776470588235294 0.756862745098039 0.737254901960784 1" />
            </material>
        </visual>
        <collision>
            <origin xyz="0 0 0" rpy="0 0 0" />
            <geometry>
                <mesh filename="package://haiheng-URDF/meshes/BASE_S.STL" />
            </geometry>
        </collision>
    </link>
    <link name="WAIST_R_S">
        <inertial>
            <origin xyz="0.0393390630671425 0.000261383820259535 0.00446046426040947" rpy="0 0 0" />
            <mass value="0.405164746131843" />
            <inertia ixx="0.000364685421356772" ixy="-2.22270546072105E-06" ixz="-6.33398085775237E-05" iyy="0.00041458524721963" iyz="-1.15408706983202E-07" izz="0.000436550692987706" />
        </inertial>
        <visual>
            <origin xyz="0 0 0" rpy="0 0 0" />
            <geometry>
                <mesh filename="package://haiheng-URDF/meshes/WAIST_R_S.STL" />
            </geometry>
            <material name="">
                <color rgba="0.776470588235294 0.756862745098039 0.737254901960784 1" />
            </material>
        </visual>
        <collision>
            <origin xyz="0 0 0" rpy="0 0 0" />
            <geometry>
                <mesh filename="package://haiheng-URDF/meshes/WAIST_R_S.STL" />
            </geometry>
        </collision>
    </link>
    <joint name="WAIST_R" type="revolute">
        <origin xyz="-0.0480866409367944 0 0.0735" rpy="0 0 0" />
        <parent link="BASE_S" />
        <child link="WAIST_R_S" />
        <axis xyz="1 0 0" />
        <limit lower="-0.34907" upper="0.43633" effort="32" velocity="6.39" />
    </joint>
    <link name="WAIST_Y_S">
        <inertial>
            <origin xyz="5.98647386154653E-05 0.00470123124229919 0.042651703033631" rpy="0 0 0" />
            <mass value="0.470653831863834" />
            <inertia ixx="0.00050447381298539" ixy="-1.71653732990785E-07" ixz="-2.11804679474508E-06" iyy="0.000541827540054521" iyz="-6.93772579914683E-05" izz="0.000440057300172382" />
        </inertial>
        <visual>
            <origin xyz="0 0 0" rpy="0 0 0" />
            <geometry>
                <mesh filename="package://haiheng-URDF/meshes/WAIST_Y_S.STL" />
            </geometry>
            <material name="">
                <color rgba="0.776470588235294 0.756862745098039 0.737254901960784 1" />
            </material>
        </visual>
        <collision>
            <origin xyz="0 0 0" rpy="0 0 0" />
            <geometry>
                <mesh filename="package://haiheng-URDF/meshes/WAIST_Y_S.STL" />
            </geometry>
        </collision>
    </link>
    <joint name="WAIST_Y" type="revolute">
        <origin xyz="0.0528000000000001 0 0.044" rpy="0 0 0" />
        <parent link="WAIST_R_S" />
        <child link="WAIST_Y_S" />
        <axis xyz="0 0 -1" />
        <limit lower="-0.17453" upper="0.17453" effort="32" velocity="6.39" />
    </joint>
    <link name="WAIST_P_S">
        <inertial>
            <origin xyz="-0.0284152290251959 -0.049390837591773 0.140919549101816" rpy="0 0 0" />
            <mass value="3.28930625122278" />
            <inertia ixx="0.011223125800322" ixy="6.960400213984E-06" ixz="2.55573490924923E-05" iyy="0.00768225796761723" iyz="9.27417241477526E-05" izz="0.00569770153178116" />
        </inertial>
        <visual>
            <origin xyz="0 0 0" rpy="0 0 0" />
            <geometry>
                <mesh filename="package://haiheng-URDF/meshes/WAIST_P_S.STL" />
            </geometry>
            <material name="">
                <color rgba="0.776470588235294 0.756862745098039 0.737254901960784 1" />
            </material>
        </visual>
        <collision>
            <origin xyz="0 0 0" rpy="0 0 0" />
            <geometry>
                <mesh filename="package://haiheng-URDF/meshes/WAIST_P_S.STL" />
            </geometry>
        </collision>
    </link>
    <joint name="WAIST_P" type="revolute">
        <origin xyz="0 0.0475000000000001 0.055" rpy="0 0 0" />
        <parent link="WAIST_Y_S" />
        <child link="WAIST_P_S" />
        <axis xyz="0 -1 0" />
        <limit lower="-0.5236" upper="0.5236" effort="32" velocity="6.39" />
    </joint>
    <link name="R_SHOULDER_P_S">
        <inertial>
            <origin xyz="0.00309655891711459 -0.0404648743589515 -5.70204534988683E-06" rpy="0 0 0" />
            <mass value="0.233170111171462" />
            <inertia ixx="0.000171998984172012" ixy="1.46790887156413E-05" ixz="-1.1154207454842E-08" iyy="0.000140303407938069" iyz="6.69602289984184E-09" izz="0.000160172071088882" />
        </inertial>
        <visual>
            <origin xyz="0 0 0" rpy="0 0 0" />
            <geometry>
                <mesh filename="package://haiheng-URDF/meshes/R_SHOULDER_P_S.STL" />
            </geometry>
            <material name="">
                <color rgba="0.466666666666667 0.466666666666667 1 1" />
            </material>
        </visual>
        <collision>
            <origin xyz="0 0 0" rpy="0 0 0" />
            <geometry>
                <mesh filename="package://haiheng-URDF/meshes/R_SHOULDER_P_S.STL" />
            </geometry>
        </collision>
    </link>
    <joint name="R_SHOULDER_P" type="revolute">
        <origin xyz="0 -0.165499999999996 0.257000000000003" rpy="0 0 0" />
        <parent link="WAIST_P_S" />
        <child link="R_SHOULDER_P_S" />
        <axis xyz="0 -1 0" />
        <limit lower="-3.1416" upper="3.1416" effort="30" velocity="3.56" />
    </joint>
    <link name="R_SHOULDER_R_S">
        <inertial>
            <origin xyz="-0.0284679914184296 -0.0581440526599475 -7.40042664926222E-08" rpy="0 0 0" />
            <mass value="0.257428149742434" />
            <inertia ixx="0.000335929223093836" ixy="-8.89393807602445E-05" ixz="1.71179227331045E-10" iyy="0.000191925855028058" iyz="-1.53396681202461E-12" izz="0.000382143005741085" />
        </inertial>
        <visual>
            <origin xyz="0 0 0" rpy="0 0 0" />
            <geometry>
                <mesh filename="package://haiheng-URDF/meshes/R_SHOULDER_R_S.STL" />
            </geometry>
            <material name="">
                <color rgba="0.890196078431372 0.890196078431372 0.913725490196078 1" />
            </material>
        </visual>
        <collision>
            <origin xyz="0 0 0" rpy="0 0 0" />
            <geometry>
                <mesh filename="package://haiheng-URDF/meshes/R_SHOULDER_R_S.STL" />
            </geometry>
        </collision>
    </link>
    <joint name="R_SHOULDER_R" type="revolute">
        <origin xyz="0.0314999999999992 -0.0630000000000003 0" rpy="0 0 0" />
        <parent link="R_SHOULDER_P_S" />
        <child link="R_SHOULDER_R_S" />
        <axis xyz="1 0 0" />
        <limit lower="-0.5236" upper="1.5708" effort="30" velocity="3.56" />
    </joint>
    <link name="R_SHOULDER_Y_S">
        <inertial>
            <origin xyz="0.000667702402222874 -0.0566182468520725 0.000330537658195462" rpy="0 0 0" />
            <mass value="0.176101027388559" />
            <inertia ixx="0.000133080610538404" ixy="1.59356591874821E-05" ixz="-1.45120043826288E-07" iyy="6.37626095396424E-05" iyz="-3.11283351075383E-07" izz="0.000124992042640814" />
        </inertial>
        <visual>
            <origin xyz="0 0 0" rpy="0 0 0" />
            <geometry>
                <mesh filename="package://haiheng-URDF/meshes/R_SHOULDER_Y_S.STL" />
            </geometry>
            <material name="">
                <color rgba="0.890196078431372 0.890196078431372 0.913725490196078 1" />
            </material>
        </visual>
        <collision>
            <origin xyz="0 0 0" rpy="0 0 0" />
            <geometry>
                <mesh filename="package://haiheng-URDF/meshes/R_SHOULDER_Y_S.STL" />
            </geometry>
        </collision>
    </link>
    <joint name="R_SHOULDER_Y" type="revolute">
        <origin xyz="-0.0314999999998622 -0.1425 0" rpy="0 0 0" />
        <parent link="R_SHOULDER_R_S" />
        <child link="R_SHOULDER_Y_S" />
        <axis xyz="0 -1 0" />
        <limit lower="-3.1416" upper="3.1416" effort="9.6" velocity="3.87" />
    </joint>
    <link name="R_ELBOW_Y_S">
        <inertial>
            <origin xyz="-0.02604153600278 -0.0542622429439206 -5.65550100528611E-07" rpy="0 0 0" />
            <mass value="0.199352770077607" />
            <inertia ixx="0.00016650122641763" ixy="-4.23819858576262E-05" ixz="1.89179405248977E-09" iyy="0.000100849389036715" iyz="9.56389457202389E-09" izz="0.000183547297059709" />
        </inertial>
        <visual>
            <origin xyz="0 0 0" rpy="0 0 0" />
            <geometry>
                <mesh filename="package://haiheng-URDF/meshes/R_ELBOW_Y_S.STL" />
            </geometry>
            <material name="">
                <color rgba="1 1 0.501960784313725 1" />
            </material>
        </visual>
        <collision>
            <origin xyz="0 0 0" rpy="0 0 0" />
            <geometry>
                <mesh filename="package://haiheng-URDF/meshes/R_ELBOW_Y_S.STL" />
            </geometry>
        </collision>
    </link>
    <joint name="R_ELBOW_Y" type="revolute">
        <origin xyz="0.0295999999999979 -0.0974999999999998 0" rpy="0 0 0" />
        <parent link="R_SHOULDER_Y_S" />
        <child link="R_ELBOW_Y_S" />
        <axis xyz="1 0 0" />
        <limit lower="0" upper="2.0071" effort="9.6" velocity="3.87" />
    </joint>
    <link name="R_WRIST_P_S">
        <inertial>
            <origin xyz="7.05754170134664E-06 -0.0568151287194093 0.0276933823326724" rpy="0 0 0" />
            <mass value="0.228274685241439" />
            <inertia ixx="0.00023390012782072" ixy="4.02452333571785E-08" ixz="1.26280681754248E-08" iyy="5.80173293020267E-05" iyz="3.1929703584436E-05" izz="0.000242265333180492" />
        </inertial>
        <visual>
            <origin xyz="0 0 0" rpy="0 0 0" />
            <geometry>
                <mesh filename="package://haiheng-URDF/meshes/R_WRIST_P_S.STL" />
            </geometry>
            <material name="">
                <color rgba="0.890196078431372 0.890196078431372 0.913725490196078 1" />
            </material>
        </visual>
        <collision>
            <origin xyz="0 0 0" rpy="0 0 0" />
            <geometry>
                <mesh filename="package://haiheng-URDF/meshes/R_WRIST_P_S.STL" />
            </geometry>
        </collision>
    </link>
    <joint name="R_WRIST_P" type="revolute">
        <origin xyz="-0.0295999999999559 -0.11300000000001 0" rpy="0 0 0" />
        <parent link="R_ELBOW_Y_S" />
        <child link="R_WRIST_P_S" />
        <axis xyz="0 -1 0" />
        <limit lower="-3.1416" upper="3.1416" effort="6.5" velocity="4.19" />
    </joint>
    <link name="R_WRIST_Y_S">
        <inertial>
            <origin xyz="0.00695653036993677 -0.000259557636742902 -0.0243702899956799" rpy="0 0 0" />
            <mass value="0.0924240168156972" />
            <inertia ixx="2.48489216873607E-05" ixy="-7.03338206526018E-09" ixz="6.52991278374128E-06" iyy="2.72009165904772E-05" iyz="-5.63938312679387E-08" izz="2.00310442161515E-05" />
        </inertial>
        <visual>
            <origin xyz="0 0 0" rpy="0 0 0" />
            <geometry>
                <mesh filename="package://haiheng-URDF/meshes/R_WRIST_Y_S.STL" />
            </geometry>
            <material name="">
                <color rgba="0.647058823529412 0.619607843137255 0.588235294117647 1" />
            </material>
        </visual>
        <collision>
            <origin xyz="0 0 0" rpy="0 0 0" />
            <geometry>
                <mesh filename="package://haiheng-URDF/meshes/R_WRIST_Y_S.STL" />
            </geometry>
        </collision>
    </link>
    <joint name="R_WRIST_Y" type="revolute">
        <origin xyz="0 -0.115999999999999 0.0370000000000008" rpy="0 0 0" />
        <parent link="R_WRIST_P_S" />
        <child link="R_WRIST_Y_S" />
        <axis xyz="0 0 -1" />
        <limit lower="-1.3963" upper="1.3963" effort="2.8" velocity="4.71" />
    </joint>
    <link name="R_WRIST_R_S">
        <inertial>
            <origin xyz="-0.0235908304687495 -0.0751234769730799 0.0143379932487298" rpy="0 0 0" />
            <mass value="0.235474467949968" />
            <inertia ixx="9.85717167103674E-05" ixy="-1.65691795516579E-05" ixz="-9.85142239477816E-10" iyy="0.000159129939808732" iyz="-9.55665044338457E-07" izz="0.000157480984009903" />
        </inertial>
        <visual>
            <origin xyz="0 0 0" rpy="0 0 0" />
            <geometry>
                <mesh filename="package://haiheng-URDF/meshes/R_WRIST_R_S.STL" />
            </geometry>
            <material name="">
                <color rgba="0.776470588235294 0.756862745098039 0.737254901960784 1" />
            </material>
        </visual>
        <collision>
            <origin xyz="0 0 0" rpy="0 0 0" />
            <geometry>
                <mesh filename="package://haiheng-URDF/meshes/R_WRIST_R_S.STL" />
            </geometry>
        </collision>
    </link>
    <joint name="R_WRIST_R" type="revolute">
        <origin xyz="0.026 0 -0.037" rpy="0 0 0" />
        <parent link="R_WRIST_Y_S" />
        <child link="R_WRIST_R_S" />
        <axis xyz="1 0 0" />
        <limit lower="-1.5708" upper="1.5708" effort="2.8" velocity="4.71" />
    </joint>
    <link name="R_GRIPPER_Y_S">
        <inertial>
            <origin xyz="-0.0181544184075183 0.727692680310497 -0.103415953849942" rpy="0 0 0" />
            <mass value="21.9672729386467" />
            <inertia ixx="3.28612844272299" ixy="0.013507096998534" ixz="-0.0654584384436809" iyy="0.557728510457513" iyz="0.110231187648778" izz="2.81484887001163" />
        </inertial>
        <visual>
            <origin xyz="0 0 0" rpy="0 0 0" />
            <geometry>
                <mesh filename="package://haiheng-URDF/meshes/R_GRIPPER_Y_S.STL" />
            </geometry>
            <material name="">
                <color rgba="0.776470588235294 0.756862745098039 0.737254901960784 1" />
            </material>
        </visual>
        <collision>
            <origin xyz="0 0 0" rpy="0 0 0" />
            <geometry>
                <mesh filename="package://haiheng-URDF/meshes/R_GRIPPER_Y_S.STL" />
            </geometry>
        </collision>
    </link>
    <joint name="R_GRIPPER_Y" type="fixed">
        <origin xyz="-0.025999999999898 -0.117700000000003 0" rpy="0 0 0" />
        <parent link="R_WRIST_R_S" />
        <child link="R_GRIPPER_Y_S" />
        <axis xyz="0 0 0" />
        <limit lower="0" upper="0" effort="0" velocity="0" />
    </joint>
    <link name="R_GRIPPER_END_S">
        <inertial>
            <origin xyz="-0.0181544184075183 1.727692680310497 -0.103415953849942" rpy="0 0 0" />
            <mass value="0" />
            <inertia ixx="0" ixy="0" ixz="0" iyy="0" iyz="0" izz="0" />
        </inertial>
    </link>
    <joint name="R_GRIPPER_END" type="fixed">
        <origin xyz="-0.025999999999898 -0.243700000000003 0" rpy="0 0 0" />
        <parent link="R_WRIST_R_S" />
        <child link="R_GRIPPER_END_S" />
        <axis xyz="0 0 0" />
        <limit lower="0" upper="0" effort="0" velocity="0" />
    </joint>
    <link name="R_CAMERA_S">
        <inertial>
            <origin xyz="0.00230031159113075 0.0011119909721718 0.0124721651252537" rpy="0 0 0" />
            <mass value="0.0800000786815629" />
            <inertia ixx="4.8227582450399E-05" ixy="7.16175736896557E-07" ixz="1.2980215755891E-08" iyy="7.23232333249883E-06" iyz="-2.56110672052591E-09" izz="4.87241532031086E-05" />
        </inertial>
        <visual>
            <origin xyz="0 0 0" rpy="0 0 0" />
            <geometry>
                <mesh filename="package://haiheng-URDF/meshes/R_CAMERA_S.STL" />
            </geometry>
            <material name="">
                <color rgba="0.792156862745098 0.819607843137255 0.933333333333333 1" />
            </material>
        </visual>
        <collision>
            <origin xyz="0 0 0" rpy="0 0 0" />
            <geometry>
                <mesh filename="package://haiheng-URDF/meshes/R_CAMERA_S.STL" />
            </geometry>
        </collision>
    </link>
    <joint name="R_CAMERA" type="fixed">
        <origin xyz="-0.026 -0.087965 0.10786" rpy="3.1416 0 -1.5708" />
        <parent link="R_WRIST_R_S" />
        <child link="R_CAMERA_S" />
        <axis xyz="0 0 0" />
    </joint>
    <link name="L_SHOULDER_P_S">
        <inertial>
            <origin xyz="0.00309655937137763 0.0404647066484357 5.4819975956466E-06" rpy="0 0 0" />
            <mass value="0.233170111156788" />
            <inertia ixx="0.000171998984169381" ixy="-1.46790906648578E-05" ixz="1.11542376924262E-08" iyy="0.000140303407930708" iyz="6.6962323689226E-09" izz="0.000160172071080473" />
        </inertial>
        <visual>
            <origin xyz="0 0 0" rpy="0 0 0" />
            <geometry>
                <mesh filename="package://haiheng-URDF/meshes/L_SHOULDER_P_S.STL" />
            </geometry>
            <material name="">
                <color rgba="0.466666666666667 0.466666666666667 1 1" />
            </material>
        </visual>
        <collision>
            <origin xyz="0 0 0" rpy="0 0 0" />
            <geometry>
                <mesh filename="package://haiheng-URDF/meshes/L_SHOULDER_P_S.STL" />
            </geometry>
        </collision>
    </link>
    <joint name="L_SHOULDER_P" type="revolute">
        <origin xyz="0 0.0705000000000039 0.257" rpy="0 0 0" />
        <parent link="WAIST_P_S" />
        <child link="L_SHOULDER_P_S" />
        <axis xyz="0 1 0" />
        <limit lower="-3.1416" upper="3.1416" effort="30" velocity="3.56" />
    </joint>
    <link name="L_SHOULDER_R_S">
        <inertial>
            <origin xyz="-0.0284611190875016 0.058144042426691 7.36259933020733E-08" rpy="0 0 0" />
            <mass value="0.257428147687526" />
            <inertia ixx="0.000335929222119726" ixy="8.89393847956866E-05" ixz="-1.71960690566475E-10" iyy="0.000191925853285239" iyz="-1.33911001795188E-12" izz="0.000382143004914352" />
        </inertial>
        <visual>
            <origin xyz="0 0 0" rpy="0 0 0" />
            <geometry>
                <mesh filename="package://haiheng-URDF/meshes/L_SHOULDER_R_S.STL" />
            </geometry>
            <material name="">
                <color rgba="0.890196078431372 0.890196078431372 0.913725490196078 1" />
            </material>
        </visual>
        <collision>
            <origin xyz="0 0 0" rpy="0 0 0" />
            <geometry>
                <mesh filename="package://haiheng-URDF/meshes/L_SHOULDER_R_S.STL" />
            </geometry>
        </collision>
    </link>
    <joint name="L_SHOULDER_R" type="revolute">
        <origin xyz="0.0314999999999989 0.0630000000000014 0" rpy="0 0 0" />
        <parent link="L_SHOULDER_P_S" />
        <child link="L_SHOULDER_R_S" />
        <axis xyz="1 0 0" />
        <limit lower="-0.5236" upper="1.5708" effort="30" velocity="3.56" />
    </joint>
    <link name="L_SHOULDER_Y_S">
        <inertial>
            <origin xyz="0.000667702404180174 0.0574329718305197 0.000330652041506507" rpy="0 0 0" />
            <mass value="0.176101027388559" />
            <inertia ixx="0.000133080610538405" ixy="-1.61185072660398E-05" ixz="-1.4534773629495E-07" iyy="6.37626095396427E-05" iyz="-3.11283486395296E-07" izz="0.000124992042640815" />
        </inertial>
        <visual>
            <origin xyz="0 0 0" rpy="0 0 0" />
            <geometry>
                <mesh filename="package://haiheng-URDF/meshes/L_SHOULDER_Y_S.STL" />
            </geometry>
            <material name="">
                <color rgba="0.890196078431372 0.890196078431372 0.913725490196078 1" />
            </material>
        </visual>
        <collision>
            <origin xyz="0 0 0" rpy="0 0 0" />
            <geometry>
                <mesh filename="package://haiheng-URDF/meshes/L_SHOULDER_Y_S.STL" />
            </geometry>
        </collision>
    </link>
    <joint name="L_SHOULDER_Y" type="revolute">
        <origin xyz="-0.0315000000000319 0.142499999999999 0" rpy="0 0 0" />
        <parent link="L_SHOULDER_R_S" />
        <child link="L_SHOULDER_Y_S" />
        <axis xyz="1 0 0" />
        <limit lower="-3.1416" upper="3.1416" effort="9.6" velocity="3.87" />
    </joint>
    <link name="L_ELBOW_Y_S">
        <inertial>
            <origin xyz="-0.0260415399284501 0.0542622325066571 5.64706923444902E-07" rpy="0 0 0" />
            <mass value="0.199352740840798" />
            <inertia ixx="0.000166501219877608" ixy="4.23819849574534E-05" ixz="-1.88929979456778E-09" iyy="0.000100849378854452" iyz="9.56186560859515E-09" izz="0.000183547284206065" />
        </inertial>
        <visual>
            <origin xyz="0 0 0" rpy="0 0 0" />
            <geometry>
                <mesh filename="package://haiheng-URDF/meshes/L_ELBOW_Y_S.STL" />
            </geometry>
            <material name="">
                <color rgba="1 1 0.501960784313725 1" />
            </material>
        </visual>
        <collision>
            <origin xyz="0 0 0" rpy="0 0 0" />
            <geometry>
                <mesh filename="package://haiheng-URDF/meshes/L_ELBOW_Y_S.STL" />
            </geometry>
        </collision>
    </link>
    <joint name="L_ELBOW_Y" type="revolute">
        <origin xyz="0.0296000000000016 0.0975 0" rpy="0 0 0" />
        <parent link="L_SHOULDER_Y_S" />
        <child link="L_ELBOW_Y_S" />
        <axis xyz="1 0 0" />
        <limit lower="0" upper="2.0071" effort="9.6" velocity="3.87" />
    </joint>
    <link name="L_WRIST_P_S">
        <inertial>
            <origin xyz="7.05753898336532E-06 0.0565214183249297 0.0277412314337067" rpy="0 0 0" />
            <mass value="0.22827468523835" />
            <inertia ixx="0.00023390012782042" ixy="4.02452326933586E-08" ixz="1.26280415018441E-08" iyy="5.8017329301398E-05" iyz="-3.19589228031104E-05" izz="0.000242265333179572" />
        </inertial>
        <visual>
            <origin xyz="0 0 0" rpy="0 0 0" />
            <geometry>
                <mesh filename="package://haiheng-URDF/meshes/L_WRIST_P_S.STL" />
            </geometry>
            <material name="">
                <color rgba="0.890196078431372 0.890196078431372 0.913725490196078 1" />
            </material>
        </visual>
        <collision>
            <origin xyz="0 0 0" rpy="0 0 0" />
            <geometry>
                <mesh filename="package://haiheng-URDF/meshes/L_WRIST_P_S.STL" />
            </geometry>
        </collision>
    </link>
    <joint name="L_WRIST_P" type="revolute">
        <origin xyz="-0.0296000000000115 0.113000000000001 0" rpy="0 0 0" />
        <parent link="L_ELBOW_Y_S" />
        <child link="L_WRIST_P_S" />
        <axis xyz="0 1 0" />
        <limit lower="-3.1416" upper="3.1416" effort="6.5" velocity="4.19" />
    </joint>
    <link name="L_WRIST_Y_S">
        <inertial>
            <origin xyz="0.00695653036978421 -0.000328963835835694 -0.0245082816282673" rpy="0 0 0" />
            <mass value="0.0924240168156964" />
            <inertia ixx="2.48489216873607E-05" ixy="-3.38147727471612E-09" ixz="6.52746807335408E-06" iyy="2.72603661121739E-05" iyz="-6.34032308587488E-08" izz="1.99715946944543E-05" />
        </inertial>
        <visual>
            <origin xyz="0 0 0" rpy="0 0 0" />
            <geometry>
                <mesh filename="package://haiheng-URDF/meshes/L_WRIST_Y_S.STL" />
            </geometry>
            <material name="">
                <color rgba="0.647058823529412 0.619607843137255 0.588235294117647 1" />
            </material>
        </visual>
        <collision>
            <origin xyz="0 0 0" rpy="0 0 0" />
            <geometry>
                <mesh filename="package://haiheng-URDF/meshes/L_WRIST_Y_S.STL" />
            </geometry>
        </collision>
    </link>
    <joint name="L_WRIST_Y" type="revolute">
        <origin xyz="0 0.116 0.036999999999999" rpy="0 0 0" />
        <parent link="L_WRIST_P_S" />
        <child link="L_WRIST_Y_S" />
        <axis xyz="0 0 -1" />
        <limit lower="-1.3963" upper="1.3963" effort="2.8" velocity="4.71" />
    </joint>
    <link name="L_WRIST_R_S">
        <inertial>
            <origin xyz="-0.022905338744649 0.0666292794681088 -0.0150665977098414" rpy="0 0 0" />
            <mass value="0.182164590475483" />
            <inertia ixx="7.36905368818206E-05" ixy="1.65809384858554E-05" ixz="-4.18450406040933E-09" iyy="0.000110978613921793" iyz="-1.74205226422112E-06" izz="0.000136709765514924" />
        </inertial>
        <visual>
            <origin xyz="0 0 0" rpy="0 0 0" />
            <geometry>
                <mesh filename="package://haiheng-URDF/meshes/L_WRIST_R_S.STL" />
            </geometry>
            <material name="">
                <color rgba="0.776470588235294 0.756862745098039 0.737254901960784 1" />
            </material>
        </visual>
        <collision>
            <origin xyz="0 0 0" rpy="0 0 0" />
            <geometry>
                <mesh filename="package://haiheng-URDF/meshes/L_WRIST_R_S.STL" />
            </geometry>
        </collision>
    </link>
    <joint name="L_WRIST_R" type="revolute">
        <origin xyz="0.0259999999999641 0 -0.0370000000000021" rpy="0 0 0" />
        <parent link="L_WRIST_Y_S" />
        <child link="L_WRIST_R_S" />
        <axis xyz="1 0 0" />
        <limit lower="-0.08727" upper="1.5533" effort="2.8" velocity="4.71" />
    </joint>
    <link name="L_HAND_Y_S">
        <inertial>
            <origin xyz="-5.72068687591627E-14 0.0467999999999995 1.90958360235527E-14" rpy="0 0 0" />
            <mass value="0.0313191340662408" />
            <inertia ixx="1.64216659620656E-05" ixy="7.79821667910323E-19" ixz="3.25289180939242E-32" iyy="1.89480761100757E-06" iyz="1.9999696702891E-19" izz="1.64216659620656E-05" />
        </inertial>
        <visual>
            <origin xyz="0 0 0" rpy="0 0 0" />
            <geometry>
                <mesh filename="package://haiheng-URDF/meshes/L_HAND_Y_S.STL" />
            </geometry>
            <material name="">
                <color rgba="0.776470588235294 0.756862745098039 0.737254901960784 1" />
            </material>
        </visual>
        <collision>
            <origin xyz="0 0 0" rpy="0 0 0" />
            <geometry>
                <mesh filename="package://haiheng-URDF/meshes/L_HAND_Y_S.STL" />
            </geometry>
        </collision>
    </link>
    <joint name="L_HAND_Y" type="fixed">
        <origin xyz="-0.0260000000005307 0.107700000000001 0" rpy="0 0 0" />
        <parent link="L_WRIST_R_S" />
        <child link="L_HAND_Y_S" />
        <axis xyz="0 0 0" />
        <limit lower="0" upper="0" effort="0" velocity="0" />
    </joint>
    <link name="NECK_Y_S">
        <inertial>
            <origin xyz="-1.3646442329795E-07 -0.0282348334691383 0.0512082478268128" rpy="0 0 0" />
            <mass value="0.192499027735237" />
            <inertia ixx="0.000177685061868272" ixy="7.88619108722079E-13" ixz="-7.00415937771692E-13" iyy="0.00017845019313067" iyz="3.397523758218E-05" izz="6.00601106455392E-05" />
        </inertial>
        <visual>
            <origin xyz="0 0 0" rpy="0 0 0" />
            <geometry>
                <mesh filename="package://haiheng-URDF/meshes/NECK_Y_S.STL" />
            </geometry>
            <material name="">
                <color rgba="0.866666666666667 0.866666666666667 0.890196078431372 1" />
            </material>
        </visual>
        <collision>
            <origin xyz="0 0 0" rpy="0 0 0" />
            <geometry>
                <mesh filename="package://haiheng-URDF/meshes/NECK_Y_S.STL" />
            </geometry>
        </collision>
    </link>
    <joint name="NECK_Y" type="revolute">
        <origin xyz="0 -0.0474999999999959 0.299" rpy="0 0 0" />
        <parent link="WAIST_P_S" />
        <child link="NECK_Y_S" />
        <axis xyz="0 0 1" />
        <limit lower="-1.5708" upper="1.5708" effort="6.5" velocity="4.19" />
    </joint>
    <link name="NECK_P_S">
        <inertial>
            <origin xyz="0.0112461184199954 0.0207578862499986 -2.26047217166681E-07" rpy="0 0 0" />
            <mass value="0.0640980523024894" />
            <inertia ixx="1.89899816834301E-05" ixy="-6.44554379581545E-06" ixz="-6.39694722819313E-14" iyy="1.43101493375643E-05" iyz="-8.97386417316111E-14" izz="2.13628742515478E-05" />
        </inertial>
        <visual>
            <origin xyz="0 0 0" rpy="0 0 0" />
            <geometry>
                <mesh filename="package://haiheng-URDF/meshes/NECK_P_S.STL" />
            </geometry>
            <material name="">
                <color rgba="0.647058823529412 0.619607843137255 0.588235294117647 1" />
            </material>
        </visual>
        <collision>
            <origin xyz="0 0 0" rpy="0 0 0" />
            <geometry>
                <mesh filename="package://haiheng-URDF/meshes/NECK_P_S.STL" />
            </geometry>
        </collision>
    </link>
    <joint name="NECK_P" type="revolute">
        <origin xyz="0 -0.0369999999999995 0.102000000000001" rpy="0 0 0" />
        <parent link="NECK_Y_S" />
        <child link="NECK_P_S" />
        <axis xyz="0 1 0" />
        <limit lower="-0.5236" upper="0.69813" effort="2.8" velocity="4.71" />
    </joint>
    <link name="NECK_R_S">
        <inertial>
            <origin xyz="-0.0102746176977244 2.75173126620916E-06 0.0980498207587623" rpy="0 0 0" />
            <mass value="0.184063327754896" />
            <inertia ixx="0.000208574867389061" ixy="-2.60554731436641E-10" ixz="2.11180516800234E-06" iyy="0.000226704299902309" iyz="-3.42708254375998E-09" izz="8.1197327642854E-05" />
        </inertial>
        <visual>
            <origin xyz="0 0 0" rpy="0 0 0" />
            <geometry>
                <mesh filename="package://haiheng-URDF/meshes/NECK_R_S.STL" />
            </geometry>
            <material name="">
                <color rgba="0.776470588235294 0.756862745098039 0.737254901960784 1" />
            </material>
        </visual>
        <collision>
            <origin xyz="0 0 0" rpy="0 0 0" />
            <geometry>
                <mesh filename="package://haiheng-URDF/meshes/NECK_R_S.STL" />
            </geometry>
        </collision>
    </link>
    <joint name="NECK_R" type="revolute">
        <origin xyz="0.026 0.0369999999999997 0" rpy="0 0 0" />
        <parent link="NECK_P_S" />
        <child link="NECK_R_S" />
        <axis xyz="1 0 0" />
        <limit lower="-0.2618" upper="0.2618" effort="2.8" velocity="4.71" />
    </joint>
    <link name="NECK_CAM_S">
        <inertial>
            <origin xyz="0.00230031187546603 0.00111198018493727 0.0124721593275665" rpy="0 0 0" />
            <mass value="0.0800000395910102" />
            <inertia ixx="4.82275844460153E-05" ixy="7.16176094495532E-07" ixz="1.29782593586995E-08" iyy="7.23236082982756E-06" iyz="-2.55656493035001E-09" izz="4.87241135848016E-05" />
        </inertial>
        <visual>
            <origin xyz="0 0 0" rpy="0 0 0" />
            <geometry>
                <mesh filename="package://haiheng-URDF/meshes/NECK_CAM_S.STL" />
            </geometry>
            <material name="">
                <color rgba="0.792156862745098 0.819607843137255 0.933333333333333 1" />
            </material>
        </visual>
        <collision>
            <origin xyz="0 0 0" rpy="0 0 0" />
            <geometry>
                <mesh filename="package://haiheng-URDF/meshes/NECK_CAM_S.STL" />
            </geometry>
        </collision>
    </link>
    <joint name="NECK_CAM" type="fixed">
        <origin xyz="0.0530465958483486 0 0.0916469819777312" rpy="0 0.261799387799151 0" />
        <parent link="NECK_R_S" />
        <child link="NECK_CAM_S" />
        <axis xyz="0 0 0" />
        <limit lower="0" upper="0" effort="0" velocity="0" />
    </joint>
    <link name="FRONT_CAMERA_S">
        <inertial>
            <origin xyz="0.00230031159113053 0.00111199097217157 0.0124721651252535" rpy="0 0 0" />
            <mass value="0.0800000786815634" />
            <inertia ixx="4.82275824503994E-05" ixy="7.16175736897066E-07" ixz="1.29802157559639E-08" iyy="7.23232333249883E-06" iyz="-2.56110672198687E-09" izz="4.87241532031088E-05" />
        </inertial>
        <visual>
            <origin xyz="0 0 0" rpy="0 0 0" />
            <geometry>
                <mesh filename="package://haiheng-URDF/meshes/FRONT_CAMERA_S.STL" />
            </geometry>
            <material name="">
                <color rgba="0.792156862745098 0.819607843137255 0.933333333333333 1" />
            </material>
        </visual>
        <collision>
            <origin xyz="0 0 0" rpy="0 0 0" />
            <geometry>
                <mesh filename="package://haiheng-URDF/meshes/FRONT_CAMERA_S.STL" />
            </geometry>
        </collision>
    </link>
    <joint name="FRONT_CAMERA" type="fixed">
        <origin xyz="0.0781499999999947 -0.0475000000000062 0.0729999999998284" rpy="0 0 0" />
        <parent link="WAIST_P_S" />
        <child link="FRONT_CAMERA_S" />
        <axis xyz="0 0 0" />
        <limit lower="0" upper="0" effort="0" velocity="0" />
    </joint>
    <link name="BEHIND_CAMERA_S">
        <inertial>
            <origin xyz="0.00230031049132706 0.0011119749626879 0.012472158594818" rpy="0 0 0" />
            <mass value="0.080000025395855" />
            <inertia ixx="4.8227593079009E-05" ixy="7.16181423711147E-07" ixz="1.29778635761497E-08" iyy="7.23240312197772E-06" iyz="-2.55264886983733E-09" izz="4.87240800745428E-05" />
        </inertial>
        <visual>
            <origin xyz="0 0 0" rpy="0 0 0" />
            <geometry>
                <mesh filename="package://haiheng-URDF/meshes/BEHIND_CAMERA_S.STL" />
            </geometry>
            <material name="">
                <color rgba="0.792156862745098 0.819607843137255 0.933333333333333 1" />
            </material>
        </visual>
        <collision>
            <origin xyz="0 0 0" rpy="0 0 0" />
            <geometry>
                <mesh filename="package://haiheng-URDF/meshes/BEHIND_CAMERA_S.STL" />
            </geometry>
        </collision>
    </link>
    <joint name="BEHIND_CAMERA" type="fixed">
        <origin xyz="-0.136513462179311 -0.0474999999999852 0.143138830158048" rpy="0 0.506145483078361 -3.14159265358978" />
        <parent link="WAIST_P_S" />
        <child link="BEHIND_CAMERA_S" />
        <axis xyz="0 0 0" />
        <limit lower="0" upper="0" effort="0" velocity="0" />
    </joint>
    <transmission name="trans_WAIST_R">
        <type>transmission_interface/SimpleTransmission</type>
        <joint name="WAIST_R">
            <hardwareInterface>hardware_interface/EffortJointInterface</hardwareInterface>
        </joint>
        <actuator name="WAIST_R_motor">
            <hardwareInterface>hardware_interface/EffortJointInterface</hardwareInterface>
            <mechanicalReduction>1</mechanicalReduction>
        </actuator>
    </transmission>
    <transmission name="trans_WAIST_Y">
        <type>transmission_interface/SimpleTransmission</type>
        <joint name="WAIST_Y">
            <hardwareInterface>hardware_interface/EffortJointInterface</hardwareInterface>
        </joint>
        <actuator name="WAIST_Y_motor">
            <hardwareInterface>hardware_interface/EffortJointInterface</hardwareInterface>
            <mechanicalReduction>1</mechanicalReduction>
        </actuator>
    </transmission>
    <transmission name="trans_WAIST_P">
        <type>transmission_interface/SimpleTransmission</type>
        <joint name="WAIST_P">
            <hardwareInterface>hardware_interface/EffortJointInterface</hardwareInterface>
        </joint>
        <actuator name="WAIST_P_motor">
            <hardwareInterface>hardware_interface/EffortJointInterface</hardwareInterface>
            <mechanicalReduction>1</mechanicalReduction>
        </actuator>
    </transmission>
    <transmission name="trans_R_SHOULDER_P">
        <type>transmission_interface/SimpleTransmission</type>
        <joint name="R_SHOULDER_P">
            <hardwareInterface>hardware_interface/EffortJointInterface</hardwareInterface>
        </joint>
        <actuator name="R_SHOULDER_P_motor">
            <hardwareInterface>hardware_interface/EffortJointInterface</hardwareInterface>
            <mechanicalReduction>1</mechanicalReduction>
        </actuator>
    </transmission>
    <transmission name="trans_R_SHOULDER_R">
        <type>transmission_interface/SimpleTransmission</type>
        <joint name="R_SHOULDER_R">
            <hardwareInterface>hardware_interface/EffortJointInterface</hardwareInterface>
        </joint>
        <actuator name="R_SHOULDER_R_motor">
            <hardwareInterface>hardware_interface/EffortJointInterface</hardwareInterface>
            <mechanicalReduction>1</mechanicalReduction>
        </actuator>
    </transmission>
    <transmission name="trans_R_SHOULDER_Y">
        <type>transmission_interface/SimpleTransmission</type>
        <joint name="R_SHOULDER_Y">
            <hardwareInterface>hardware_interface/EffortJointInterface</hardwareInterface>
        </joint>
        <actuator name="R_SHOULDER_Y_motor">
            <hardwareInterface>hardware_interface/EffortJointInterface</hardwareInterface>
            <mechanicalReduction>1</mechanicalReduction>
        </actuator>
    </transmission>
    <transmission name="trans_R_ELBOW_Y">
        <type>transmission_interface/SimpleTransmission</type>
        <joint name="R_ELBOW_Y">
            <hardwareInterface>hardware_interface/EffortJointInterface</hardwareInterface>
        </joint>
        <actuator name="R_ELBOW_Y_motor">
            <hardwareInterface>hardware_interface/EffortJointInterface</hardwareInterface>
            <mechanicalReduction>1</mechanicalReduction>
        </actuator>
    </transmission>
    <transmission name="trans_R_WRIST_P">
        <type>transmission_interface/SimpleTransmission</type>
        <joint name="R_WRIST_P">
            <hardwareInterface>hardware_interface/EffortJointInterface</hardwareInterface>
        </joint>
        <actuator name="R_WRIST_P_motor">
            <hardwareInterface>hardware_interface/EffortJointInterface</hardwareInterface>
            <mechanicalReduction>1</mechanicalReduction>
        </actuator>
    </transmission>
    <transmission name="trans_R_WRIST_Y">
        <type>transmission_interface/SimpleTransmission</type>
        <joint name="R_WRIST_Y">
            <hardwareInterface>hardware_interface/EffortJointInterface</hardwareInterface>
        </joint>
        <actuator name="R_WRIST_Y_motor">
            <hardwareInterface>hardware_interface/EffortJointInterface</hardwareInterface>
            <mechanicalReduction>1</mechanicalReduction>
        </actuator>
    </transmission>
    <transmission name="trans_R_WRIST_R">
        <type>transmission_interface/SimpleTransmission</type>
        <joint name="R_WRIST_R">
            <hardwareInterface>hardware_interface/EffortJointInterface</hardwareInterface>
        </joint>
        <actuator name="R_WRIST_R_motor">
            <hardwareInterface>hardware_interface/EffortJointInterface</hardwareInterface>
            <mechanicalReduction>1</mechanicalReduction>
        </actuator>
    </transmission>
    <transmission name="trans_L_SHOULDER_P">
        <type>transmission_interface/SimpleTransmission</type>
        <joint name="L_SHOULDER_P">
            <hardwareInterface>hardware_interface/EffortJointInterface</hardwareInterface>
        </joint>
        <actuator name="L_SHOULDER_P_motor">
            <hardwareInterface>hardware_interface/EffortJointInterface</hardwareInterface>
            <mechanicalReduction>1</mechanicalReduction>
        </actuator>
    </transmission>
    <transmission name="trans_L_SHOULDER_R">
        <type>transmission_interface/SimpleTransmission</type>
        <joint name="L_SHOULDER_R">
            <hardwareInterface>hardware_interface/EffortJointInterface</hardwareInterface>
        </joint>
        <actuator name="L_SHOULDER_R_motor">
            <hardwareInterface>hardware_interface/EffortJointInterface</hardwareInterface>
            <mechanicalReduction>1</mechanicalReduction>
        </actuator>
    </transmission>
    <transmission name="trans_L_SHOULDER_Y">
        <type>transmission_interface/SimpleTransmission</type>
        <joint name="L_SHOULDER_Y">
            <hardwareInterface>hardware_interface/EffortJointInterface</hardwareInterface>
        </joint>
        <actuator name="L_SHOULDER_Y_motor">
            <hardwareInterface>hardware_interface/EffortJointInterface</hardwareInterface>
            <mechanicalReduction>1</mechanicalReduction>
        </actuator>
    </transmission>
    <transmission name="trans_L_ELBOW_Y">
        <type>transmission_interface/SimpleTransmission</type>
        <joint name="L_ELBOW_Y">
            <hardwareInterface>hardware_interface/EffortJointInterface</hardwareInterface>
        </joint>
        <actuator name="L_ELBOW_Y_motor">
            <hardwareInterface>hardware_interface/EffortJointInterface</hardwareInterface>
            <mechanicalReduction>1</mechanicalReduction>
        </actuator>
    </transmission>
    <transmission name="trans_L_WRIST_P">
        <type>transmission_interface/SimpleTransmission</type>
        <joint name="L_WRIST_P">
            <hardwareInterface>hardware_interface/EffortJointInterface</hardwareInterface>
        </joint>
        <actuator name="L_WRIST_P_motor">
            <hardwareInterface>hardware_interface/EffortJointInterface</hardwareInterface>
            <mechanicalReduction>1</mechanicalReduction>
        </actuator>
    </transmission>
    <transmission name="trans_L_WRIST_Y">
        <type>transmission_interface/SimpleTransmission</type>
        <joint name="L_WRIST_Y">
            <hardwareInterface>hardware_interface/EffortJointInterface</hardwareInterface>
        </joint>
        <actuator name="L_WRIST_Y_motor">
            <hardwareInterface>hardware_interface/EffortJointInterface</hardwareInterface>
            <mechanicalReduction>1</mechanicalReduction>
        </actuator>
    </transmission>
    <transmission name="trans_L_WRIST_R">
        <type>transmission_interface/SimpleTransmission</type>
        <joint name="L_WRIST_R">
            <hardwareInterface>hardware_interface/EffortJointInterface</hardwareInterface>
        </joint>
        <actuator name="L_WRIST_R_motor">
            <hardwareInterface>hardware_interface/EffortJointInterface</hardwareInterface>
            <mechanicalReduction>1</mechanicalReduction>
        </actuator>
    </transmission>
    <transmission name="trans_NECK_Y">
        <type>transmission_interface/SimpleTransmission</type>
        <joint name="NECK_Y">
            <hardwareInterface>hardware_interface/EffortJointInterface</hardwareInterface>
        </joint>
        <actuator name="NECK_Y_motor">
            <hardwareInterface>hardware_interface/EffortJointInterface</hardwareInterface>
            <mechanicalReduction>1</mechanicalReduction>
        </actuator>
    </transmission>
    <transmission name="trans_NECK_P">
        <type>transmission_interface/SimpleTransmission</type>
        <joint name="NECK_P">
            <hardwareInterface>hardware_interface/EffortJointInterface</hardwareInterface>
        </joint>
        <actuator name="NECK_P_motor">
            <hardwareInterface>hardware_interface/EffortJointInterface</hardwareInterface>
            <mechanicalReduction>1</mechanicalReduction>
        </actuator>
    </transmission>
    <transmission name="trans_NECK_R">
        <type>transmission_interface/SimpleTransmission</type>
        <joint name="NECK_R">
            <hardwareInterface>hardware_interface/EffortJointInterface</hardwareInterface>
        </joint>
        <actuator name="NECK_R_motor">
            <hardwareInterface>hardware_interface/EffortJointInterface</hardwareInterface>
            <mechanicalReduction>1</mechanicalReduction>
        </actuator>
    </transmission>
    <gazebo>
        <plugin name="gazebo_ros_control" filename="libgazebo_ros_control.so">
            <robotNamespace>/</robotNamespace>
        </plugin>
    </gazebo>
</robot>

